Workbook

Sheet LEEME
A1: hoja | B1: descripcion
A2: Sectores | B2: Un sector por fila (zona censal). macrozona: distrito al que pertenece (cada sector en una sola).
A3: Sitios (falta que el liu calcule contenedores por punto limpio, para poner bien la superficie para contenedores) | B3: Ubicaciones candidatas (incluye las actuales). macrozona: dónde está el sitio. superficie: espacio para contenedores.
A4: PuntosActuales | B4: Los puntos limpios que existen hoy, el sitio donde están y su nombre municipal (el mismo que usa DotacionActual).
A5: Materiales | B5: Las 5 categorías del DS 12. atractivo_no_reciclar: uN de cada material, calibrado en la hoja Calibracion con las toneladas 2023.
A6: TiposContenedor | B6: Opciones de compra: capacidad máxima nominal por volumen y densidad, limitada además por la carga del fabricante (100 %; sin margen operativo de 20 %).
A7: DotacionActual | B7: Dotación inicial ESTIMADA (no inventario histórico) por punto y material, usando el máximo semanal de los residuos recibidos en 2023 y el 100 % de la capacidad físicamente admisible; sin gasto de adquisición.
A8: Generacion | B8: Generación anual por habitante de cada material en cada sector.
A9: Semanas | B9: Una fila por semana del horizonte. fraccion_generacion: parte de la generación anual que ocurre esa semana. temporada solo se usa para gráficos.
A10: AtractivoSitios | B10: Pares sector–sitio con distancia euclidiana <= Dmax; atractivo exp(-beta·distancia). Base: Dmax=2 km, beta=0.5/km (calibrado con las toneladas 2023, ver Calibracion). Fuera del radio se omiten y su atractivo es 0.
A11: Alternativas | B11: Una fila por cada material que recibe cada alternativa de terceros.
A12: AtractivoAlternativas | B12: Pares sector–alternativa con distancia euclidiana <= Dmax; mismo beta y radio que AtractivoSitios. Fuera del radio se omiten y su atractivo es 0.
... A18: PARÁMETROS DE ATRACTIVO | B18: Valor / interpretación
A19: beta [1/km] | B19: 0.5
A20: Dmax [km] | B20: 2
A21: Representación | B21: Solo pares dentro del radio; todos los demás tienen atractivo cero y se omiten.
A22: Para cambiar Dmax | B22: Regenerar AtractivoSitios y AtractivoAlternativas desde Coordenadas (el cambio de celda no agrega filas).
A23: Calibracion | B23: Cálculo de uN por material según calibracion_uN.pdf: cada uN hace que el modelo logit reproduzca las toneladas 2023 de ese material en los 6 puntos que calibran. El código no lee esta hoja.

Sheet Sectores
A1: sector | B1: macrozona | C1: poblacion [hab]
A2: Z1 | B2: Sur Oriente | C2: 2849
A3: Z2 | B3: Sur Oriente | C3: 5671
A4: Z3 | B4: Sur Oriente | C4: 2170
A5: Z4 | B5: Sur Oriente | C5: 1868
A6: Z5 | B6: Sur Oriente | C6: 1511
A7: Z6 | B7: Sur Oriente | C7: 3068
A8: Z7 | B8: Norte Oriente | C8: 3975
A9: Z8 | B9: Norte Oriente | C9: 3739
A10: Z9 | B10: Norte Oriente | C10: 1825
A11: Z10 | B11: Norte Oriente | C11: 4171
A12: Z11 | B12: Norte Oriente | C12: 2572
A13: Z12 | B13: Norte Oriente | C13: 5622
... A143: Z142 | B143: Sur Oriente | C143: 4166

Sheet Sitios
A1: sitio | B1: macrozona | C1: superficie [m2]
A2: S1 | B2: Sur Poniente | C2: 420
A3: S2 | B3: Norte Oriente | C3: 480
A4: S3 | B4: Norte Poniente | C4: 640
A5: S4 | B5: Sur Poniente | C5: 440
A6: S5 | B6: Norte Oriente | C6: 490
A7: S6 | B7: Sur Poniente | C7: 500
A8: S7 | B8: Sur Poniente | C8: 640
A9: S8 | B9: Sur Oriente | C9: 550
A10: S9 | B10: Sur Oriente | C10: 420
A11: S10 | B11: Norte Poniente | C11: 440
A12: S11 | B12: Sur Oriente | C12: 540
A13: S12 | B13: Norte Poniente | C13: 450
... A21: S20 | B21: Norte Poniente | C21: 560

Sheet PuntosActuales
A1: punto | B1: sitio_actual | C1: nombre_sitio_actual
A2: P1 | B2: S1 | C2: Juan de Dios Malebrán
A3: P2 | B3: S2 | C3: Los Toros
A4: P3 | B4: S3 | C4: Creta
A5: P4 | B5: S4 | C5: Los Evangelistas
A6: P5 | B6: S5 | C6: Don Ramón
A7: P6 | B7: S6 | C7: Madre Tierra
A8: P7 | B8: S7 | C8: Santa Faustina

Sheet Materiales
A1: material | B1: atractivo_no_reciclar [-]
A2: papel_carton | B2: =Calibracion!$AD$4 -> 225.37263
A3: plastico | B3: =Calibracion!$AE$4 -> 679.79179
A4: vidrio | B4: =Calibracion!$AF$4 -> 40.933046
A5: metal | B5: =Calibracion!$AG$4 -> 202.60371
A6: carton_liquidos | B6: =Calibracion!$AH$4 -> 228.68973

Sheet TiposContenedor
A1: tipo | B1: material | C1: capacidad [ton/cont] | D1: superficie [m2/cont] | E1: costo_compra [CLP/cont] | F1: costo_mantencion [CLP/cont/año]
A2: PC_770 | B2: papel_carton | C2: 0.055055 | D2: 1.0164 | E2: 442150 | F2: =ROUND(E2*Costos!$B$5,0) -> 22108
A3: PC_1100 | B3: papel_carton | C3: 0.07865 | D3: 1.4659 | E3: 527043 | F3: =ROUND(E3*Costos!$B$5,0) -> 26352
A4: PL_240 | B4: plastico | C4: 0.0096 | D4: 0.42703 | E4: 96334 | F4: =ROUND(E4*Costos!$B$5,0) -> 4817
A5: PL_770 | B5: plastico | C5: 0.0308 | D5: 1.0164 | E5: 442150 | F5: =ROUND(E5*Costos!$B$5,0) -> 22108
A6: PL_1100 | B6: plastico | C6: 0.044 | D6: 1.4659 | E6: 527043 | F6: =ROUND(E6*Costos!$B$5,0) -> 26352
A7: VI_240 | B7: vidrio | C7: 0.096 | D7: 0.42703 | E7: 96334 | F7: =ROUND(E7*Costos!$B$5,0) -> 4817
A8: VI_3000 | B8: vidrio | C8: 1.5 | D8: 2.64 | E8: 1500000 | F8: =ROUND(E8*Costos!$B$5,0) -> 75000
A9: ME_240 | B9: metal | C9: 0.00864 | D9: 0.42703 | E9: 96334 | F9: =ROUND(E9*Costos!$B$5,0) -> 4817
A10: ME_770 | B10: metal | C10: 0.02772 | D10: 1.0164 | E10: 442150 | F10: =ROUND(E10*Costos!$B$5,0) -> 22108
A11: CL_770 | B11: carton_liquidos | C11: 0.02002 | D11: 1.0164 | E11: 442150 | F11: =ROUND(E11*Costos!$B$5,0) -> 22108
A12: CL_1100 | B12: carton_liquidos | C12: 0.0286 | D12: 1.4659 | E12: 527043 | F12: =ROUND(E12*Costos!$B$5,0) -> 26352

Sheet DotacionActual
A1: punto | B1: tipo_existente | C1: material | D1: cantidad [cont/punto] | E1: capacidad_util [ton/cont] | F1: superficie [m2/cont]
A2: Los Toros | B2: EX_JAULA_PC_6400 | C2: papel_carton | D2: 1 | E2: 0.4576 | F2: 3.2
A3: Los Toros | B3: EX_PL_770 | C3: plastico | D3: 4 | E3: 0.0308 | F3: 1.0608
A4: Los Toros | B4: EX_VI_CAMP_3000 | C4: vidrio | D4: 1 | E4: 1.5 | F4: 2.64
A5: Los Toros | B5: EX_ME_770 | C5: metal | D5: 1 | E5: 0.045845816 | F5: 1.0608
A6: Los Toros | B6: EX_CL_770 | C6: carton_liquidos | D6: 2 | E6: 0.02002 | F6: 1.0608
A7: Juan de Dios Malebrán | B7: EX_JAULA_PC_6400 | C7: papel_carton | D7: 1 | E7: 0.4576 | F7: 3.2
A8: Juan de Dios Malebrán | B8: EX_PL_770 | C8: plastico | D8: 5 | E8: 0.0308 | F8: 1.0608
A9: Juan de Dios Malebrán | B9: EX_VI_CAMP_3000 | C9: vidrio | D9: 1 | E9: 1.5 | F9: 2.64
A10: Juan de Dios Malebrán | B10: EX_ME_770 | C10: metal | D10: 1 | E10: 0.044412934 | F10: 1.0608
A11: Juan de Dios Malebrán | B11: EX_CL_770 | C11: carton_liquidos | D11: 2 | E11: 0.02002 | F11: 1.0608
A12: Creta | B12: EX_JAULA_PC_6400 | C12: papel_carton | D12: 1 | E12: 0.4576 | F12: 3.2
A13: Creta | B13: EX_PL_770 | C13: plastico | D13: 2 | E13: 0.0308 | F13: 1.0608
... A36: Los Evangelistas | B36: EX_CL_770 | C36: carton_liquidos | D36: 1 | E36: 0.02002 | F36: 1.0608

Sheet Generacion
A1: sector | B1: material | C1: generacion [ton/hab/año]
A2: Z1 | B2: papel_carton | C2: 0.043533877
A3: Z1 | B3: plastico | C3: 0.037870933
A4: Z1 | B4: vidrio | C4: 0.01344949
A5: Z1 | B5: metal | C5: 0.0035393396
A6: Z1 | B6: carton_liquidos | C6: 0.0024775377
A7: Z2 | B7: papel_carton | C7: 0.043533877
A8: Z2 | B8: plastico | C8: 0.037870933
A9: Z2 | B9: vidrio | C9: 0.01344949
A10: Z2 | B10: metal | C10: 0.0035393396
A11: Z2 | B11: carton_liquidos | C11: 0.0024775377
A12: Z3 | B12: papel_carton | C12: 0.043533877
A13: Z3 | B13: plastico | C13: 0.037870933
... A711: Z142 | B711: carton_liquidos | C711: 0.0024775377

Sheet Semanas
A1: semana | B1: temporada | C1: fraccion_generacion [-]
A2: 1 | B2: verano | C2: 0.02351
A3: 2 | B3: verano | C3: 0.02351
A4: 3 | B4: verano | C4: 0.02351
A5: 4 | B5: verano | C5: 0.02351
A6: 5 | B6: verano | C6: 0.01947
A7: 6 | B7: verano | C7: 0.01644
A8: 7 | B8: verano | C8: 0.01644
A9: 8 | B9: verano | C9: 0.01644
A10: 9 | B10: verano | C10: 0.01777
A11: 10 | B11: resto | C11: 0.01878
A12: 11 | B12: resto | C12: 0.01878
A13: 12 | B13: resto | C13: 0.01878
... A53: 52 | B53: verano | C53: 0.02583

Sheet AtractivoSitios
A1: sector | B1: sitio | C1: atractivo [-]
A2: Z1 | B2: S9 | C2: =IF(SQRT((Coordenadas!$C$2-Coordenadas!$C$152)^2+(Coordenadas!$D$2-Coordenadas!$D$152)^2)<=LEEME!$B$20,EXP(-LEEME!$B$19*SQRT((Coordenadas!$C$2-Coordenadas!$C$152)^2+(Coordenadas!$D$2-Coordenadas!$D$152)^2)),0) -> 0.46294543
A3: Z1 | B3: S11 | C3: =IF(SQRT((Coordenadas!$C$2-Coordenadas!$C$154)^2+(Coordenadas!$D$2-Coordenadas!$D$154)^2)<=LEEME!$B$20,EXP(-LEEME!$B$19*SQRT((Coordenadas!$C$2-Coordenadas!$C$154)^2+(Coordenadas!$D$2-Coordenadas!$D$154)^2)),0) -> 0.43615439
A4: Z1 | B4: S15 | C4: =IF(SQRT((Coordenadas!$C$2-Coordenadas!$C$158)^2+(Coordenadas!$D$2-Coordenadas!$D$158)^2)<=LEEME!$B$20,EXP(-LEEME!$B$19*SQRT((Coordenadas!$C$2-Coordenadas!$C$158)^2+(Coordenadas!$D$2-Coordenadas!$D$158)^2)),0) -> 0.62262286
A5: Z1 | B5: S17 | C5: =IF(SQRT((Coordenadas!$C$2-Coordenadas!$C$160)^2+(Coordenadas!$D$2-Coordenadas!$D$160)^2)<=LEEME!$B$20,EXP(-LEEME!$B$19*SQRT((Coordenadas!$C$2-Coordenadas!$C$160)^2+(Coordenadas!$D$2-Coordenadas!$D$160)^2)),0) -> 0.67567309
A6: Z2 | B6: S9 | C6: =IF(SQRT((Coordenadas!$C$3-Coordenadas!$C$152)^2+(Coordenadas!$D$3-Coordenadas!$D$152)^2)<=LEEME!$B$20,EXP(-LEEME!$B$19*SQRT((Coordenadas!$C$3-Coordenadas!$C$152)^2+(Coordenadas!$D$3-Coordenadas!$D$152)^2)),0) -> 0.57119631
A7: Z2 | B7: S11 | C7: =IF(SQRT((Coordenadas!$C$3-Coordenadas!$C$154)^2+(Coordenadas!$D$3-Coordenadas!$D$154)^2)<=LEEME!$B$20,EXP(-LEEME!$B$19*SQRT((Coordenadas!$C$3-Coordenadas!$C$154)^2+(Coordenadas!$D$3-Coordenadas!$D$154)^2)),0) -> 0.45358644
A8: Z2 | B8: S15 | C8: =IF(SQRT((Coordenadas!$C$3-Coordenadas!$C$158)^2+(Coordenadas!$D$3-Coordenadas!$D$158)^2)<=LEEME!$B$20,EXP(-LEEME!$B$19*SQRT((Coordenadas!$C$3-Coordenadas!$C$158)^2+(Coordenadas!$D$3-Coordenadas!$D$158)^2)),0) -> 0.56857402
A9: Z2 | B9: S17 | C9: =IF(SQRT((Coordenadas!$C$3-Coordenadas!$C$160)^2+(Coordenadas!$D$3-Coordenadas!$D$160)^2)<=LEEME!$B$20,EXP(-LEEME!$B$19*SQRT((Coordenadas!$C$3-Coordenadas!$C$160)^2+(Coordenadas!$D$3-Coordenadas!$D$160)^2)),0) -> 0.59497839
A10: Z3 | B10: S1 | C10: =IF(SQRT((Coordenadas!$C$4-Coordenadas!$C$144)^2+(Coordenadas!$D$4-Coordenadas!$D$144)^2)<=LEEME!$B$20,EXP(-LEEME!$B$19*SQRT((Coordenadas!$C$4-Coordenadas!$C$144)^2+(Coordenadas!$D$4-Coordenadas!$D$144)^2)),0) -> 0.48153799
A11: Z3 | B11: S11 | C11: =IF(SQRT((Coordenadas!$C$4-Coordenadas!$C$154)^2+(Coordenadas!$D$4-Coordenadas!$D$154)^2)<=LEEME!$B$20,EXP(-LEEME!$B$19*SQRT((Coordenadas!$C$4-Coordenadas!$C$154)^2+(Coordenadas!$D$4-Coordenadas!$D$154)^2)),0) -> 0.63699155
A12: Z3 | B12: S15 | C12: =IF(SQRT((Coordenadas!$C$4-Coordenadas!$C$158)^2+(Coordenadas!$D$4-Coordenadas!$D$158)^2)<=LEEME!$B$20,EXP(-LEEME!$B$19*SQRT((Coordenadas!$C$4-Coordenadas!$C$158)^2+(Coordenadas!$D$4-Coordenadas!$D$158)^2)),0) -> 0.37234772
A13: Z3 | B13: S17 | C13: =IF(SQRT((Coordenadas!$C$4-Coordenadas!$C$160)^2+(Coordenadas!$D$4-Coordenadas!$D$160)^2)<=LEEME!$B$20,EXP(-LEEME!$B$19*SQRT((Coordenadas!$C$4-Coordenadas!$C$160)^2+(Coordenadas!$D$4-Coordenadas!$D$160)^2)),0) -> 0.83161067
A14: Z3 | B14: S20 | C14: =IF(SQRT((Coordenadas!$C$4-Coordenadas!$C$163)^2+(Coordenadas!$D$4-Coordenadas!$D$163)^2)<=LEEME!$B$20,EXP(-LEEME!$B$19*SQRT((Coordenadas!$C$4-Coordenadas!$C$163)^2+(Coordenadas!$D$4-Coordenadas!$D$163)^2)),0) -> 0.47401075
A15: Z4 | B15: S1 | C15: =IF(SQRT((Coordenadas!$C$5-Coordenadas!$C$144)^2+(Coordenadas!$D$5-Coordenadas!$D$144)^2)<=LEEME!$B$20,EXP(-LEEME!$B$19*SQRT((Coordenadas!$C$5-Coordenadas!$C$144)^2+(Coordenadas!$D$5-Coordenadas!$D$144)^2)),0) -> 0.3827932
A16: Z4 | B16: S9 | C16: =IF(SQRT((Coordenadas!$C$5-Coordenadas!$C$152)^2+(Coordenadas!$D$5-Coordenadas!$D$152)^2)<=LEEME!$B$20,EXP(-LEEME!$B$19*SQRT((Coordenadas!$C$5-Coordenadas!$C$152)^2+(Coordenadas!$D$5-Coordenadas!$D$152)^2)),0) -> 0.40624242
A17: Z4 | B17: S11 | C17: =IF(SQRT((Coordenadas!$C$5-Coordenadas!$C$154)^2+(Coordenadas!$D$5-Coordenadas!$D$154)^2)<=LEEME!$B$20,EXP(-LEEME!$B$19*SQRT((Coordenadas!$C$5-Coordenadas!$C$154)^2+(Coordenadas!$D$5-Coordenadas!$D$154)^2)),0) -> 0.51469931
A18: Z4 | B18: S15 | C18: =IF(SQRT((Coordenadas!$C$5-Coordenadas!$C$158)^2+(Coordenadas!$D$5-Coordenadas!$D$158)^2)<=LEEME!$B$20,EXP(-LEEME!$B$19*SQRT((Coordenadas!$C$5-Coordenadas!$C$158)^2+(Coordenadas!$D$5-Coordenadas!$D$158)^2)),0) -> 0.50616117
A19: Z4 | B19: S17 | C19: =IF(SQRT((Coordenadas!$C$5-Coordenadas!$C$160)^2+(Coordenadas!$D$5-Coordenadas!$D$160)^2)<=LEEME!$B$20,EXP(-LEEME!$B$19*SQRT((Coordenadas!$C$5-Coordenadas!$C$160)^2+(Coordenadas!$D$5-Coordenadas!$D$160)^2)),0) -> 0.85641518
A20: Z4 | B20: S20 | C20: =IF(SQRT((Coordenadas!$C$5-Coordenadas!$C$163)^2+(Coordenadas!$D$5-Coordenadas!$D$163)^2)<=LEEME!$B$20,EXP(-LEEME!$B$19*SQRT((Coordenadas!$C$5-Coordenadas!$C$163)^2+(Coordenadas!$D$5-Coordenadas!$D$163)^2)),0) -> 0.42095422
A21: Z5 | B21: S9 | C21: =IF(SQRT((Coordenadas!$C$6-Coordenadas!$C$152)^2+(Coordenadas!$D$6-Coordenadas!$D$152)^2)<=LEEME!$B$20,EXP(-LEEME!$B$19*SQRT((Coordenadas!$C$6-Coordenadas!$C$152)^2+(Coordenadas!$D$6-Coordenadas!$D$152)^2)),0) -> 0.45084416
A22: Z5 | B22: S11 | C22: =IF(SQRT((Coordenadas!$C$6-Coordenadas!$C$154)^2+(Coordenadas!$D$6-Coordenadas!$D$154)^2)<=LEEME!$B$20,EXP(-LEEME!$B$19*SQRT((Coordenadas!$C$6-Coordenadas!$C$154)^2+(Coordenadas!$D$6-Coordenadas!$D$154)^2)),0) -> 0.5933236
A23: Z5 | B23: S15 | C23: =IF(SQRT((Coordenadas!$C$6-Coordenadas!$C$158)^2+(Coordenadas!$D$6-Coordenadas!$D$158)^2)<=LEEME!$B$20,EXP(-LEEME!$B$19*SQRT((Coordenadas!$C$6-Coordenadas!$C$158)^2+(Coordenadas!$D$6-Coordenadas!$D$158)^2)),0) -> 0.45615602
A24: Z5 | B24: S17 | C24: =IF(SQRT((Coordenadas!$C$6-Coordenadas!$C$160)^2+(Coordenadas!$D$6-Coordenadas!$D$160)^2)<=LEEME!$B$20,EXP(-LEEME!$B$19*SQRT((Coordenadas!$C$6-Coordenadas!$C$160)^2+(Coordenadas!$D$6-Coordenadas!$D$160)^2)),0) -> 0.79179532
A25: Z5 | B25: S20 | C25: =IF(SQRT((Coordenadas!$C$6-Coordenadas!$C$163)^2+(Coordenadas!$D$6-Coordenadas!$D$163)^2)<=LEEME!$B$20,EXP(-LEEME!$B$19*SQRT((Coordenadas!$C$6-Coordenadas!$C$163)^2+(Coordenadas!$D$6-Coordenadas!$D$163)^2)),0) -> 0.38031816
A26: Z6 | B26: S9 | C26: =IF(SQRT((Coordenadas!$C$7-Coordenadas!$C$152)^2+(Coordenadas!$D$7-Coordenadas!$D$152)^2)<=LEEME!$B$20,EXP(-LEEME!$B$19*SQRT((Coordenadas!$C$7-Coordenadas!$C$152)^2+(Coordenadas!$D$7-Coordenadas!$D$152)^2)),0) -> 0.50982696
A27: Z6 | B27: S11 | C27: =IF(SQRT((Coordenadas!$C$7-Coordenadas!$C$154)^2+(Coordenadas!$D$7-Coordenadas!$D$154)^2)<=LEEME!$B$20,EXP(-LEEME!$B$19*SQRT((Coordenadas!$C$7-Coordenadas!$C$154)^2+(Coordenadas!$D$7-Coordenadas!$D$154)^2)),0) -> 0.3688338
A28: Z6 | B28: S15 | C28: =IF(SQRT((Coordenadas!$C$7-Coordenadas!$C$158)^2+(Coordenadas!$D$7-Coordenadas!$D$158)^2)<=LEEME!$B$20,EXP(-LEEME!$B$19*SQRT((Coordenadas!$C$7-Coordenadas!$C$158)^2+(Coordenadas!$D$7-Coordenadas!$D$158)^2)),0) -> 0.70729893
A29: Z6 | B29: S17 | C29: =IF(SQRT((Coordenadas!$C$7-Coordenadas!$C$160)^2+(Coordenadas!$D$7-Coordenadas!$D$160)^2)<=LEEME!$B$20,EXP(-LEEME!$B$19*SQRT((Coordenadas!$C$7-Coordenadas!$C$160)^2+(Coordenadas!$D$7-Coordenadas!$D$160)^2)),0) -> 0.53954495
A30: Z7 | B30: S2 | C30: =IF(SQRT((Coordenadas!$C$8-Coordenadas!$C$145)^2+(Coordenadas!$D$8-Coordenadas!$D$145)^2)<=LEEME!$B$20,EXP(-LEEME!$B$19*SQRT((Coordenadas!$C$8-Coordenadas!$C$145)^2+(Coordenadas!$D$8-Coordenadas!$D$145)^2)),0) -> 0.37898048
A31: Z7 | B31: S13 | C31: =IF(SQRT((Coordenadas!$C$8-Coordenadas!$C$156)^2+(Coordenadas!$D$8-Coordenadas!$D$156)^2)<=LEEME!$B$20,EXP(-LEEME!$B$19*SQRT((Coordenadas!$C$8-Coordenadas!$C$156)^2+(Coordenadas!$D$8-Coordenadas!$D$156)^2)),0) -> 0.8436028
A32: Z8 | B32: S2 | C32: =IF(SQRT((Coordenadas!$C$9-Coordenadas!$C$145)^2+(Coordenadas!$D$9-Coordenadas!$D$145)^2)<=LEEME!$B$20,EXP(-LEEME!$B$19*SQRT((Coordenadas!$C$9-Coordenadas!$C$145)^2+(Coordenadas!$D$9-Coordenadas!$D$145)^2)),0) -> 0.42147184
A33: Z8 | B33: S13 | C33: =IF(SQRT((Coordenadas!$C$9-Coordenadas!$C$156)^2+(Coordenadas!$D$9-Coordenadas!$D$156)^2)<=LEEME!$B$20,EXP(-LEEME!$B$19*SQRT((Coordenadas!$C$9-Coordenadas!$C$156)^2+(Coordenadas!$D$9-Coordenadas!$D$156)^2)),0) -> 0.39053436
A34: Z9 | B34: S2 | C34: =IF(SQRT((Coordenadas!$C$10-Coordenadas!$C$145)^2+(Coordenadas!$D$10-Coordenadas!$D$145)^2)<=LEEME!$B$20,EXP(-LEEME!$B$19*SQRT((Coordenadas!$C$10-Coordenadas!$C$145)^2+(Coordenadas!$D$10-Coordenadas!$D$145)^2)),0) -> 0.51012989
A35: Z9 | B35: S5 | C35: =IF(SQRT((Coordenadas!$C$10-Coordenadas!$C$148)^2+(Coordenadas!$D$10-Coordenadas!$D$148)^2)<=LEEME!$B$20,EXP(-LEEME!$B$19*SQRT((Coordenadas!$C$10-Coordenadas!$C$148)^2+(Coordenadas!$D$10-Coordenadas!$D$148)^2)),0) -> 0.5520382
A36: Z10 | B36: S2 | C36: =IF(SQRT((Coordenadas!$C$11-Coordenadas!$C$145)^2+(Coordenadas!$D$11-Coordenadas!$D$145)^2)<=LEEME!$B$20,EXP(-LEEME!$B$19*SQRT((Coordenadas!$C$11-Coordenadas!$C$145)^2+(Coordenadas!$D$11-Coordenadas!$D$145)^2)),0) -> 0.53102327
A37: Z10 | B37: S13 | C37: =IF(SQRT((Coordenadas!$C$11-Coordenadas!$C$156)^2+(Coordenadas!$D$11-Coordenadas!$D$156)^2)<=LEEME!$B$20,EXP(-LEEME!$B$19*SQRT((Coordenadas!$C$11-Coordenadas!$C$156)^2+(Coordenadas!$D$11-Coordenadas!$D$156)^2)),0) -> 0.82777775
A38: Z11 | B38: S2 | C38: =IF(SQRT((Coordenadas!$C$12-Coordenadas!$C$145)^2+(Coordenadas!$D$12-Coordenadas!$D$145)^2)<=LEEME!$B$20,EXP(-LEEME!$B$19*SQRT((Coordenadas!$C$12-Coordenadas!$C$145)^2+(Coordenadas!$D$12-Coordenadas!$D$145)^2)),0) -> 0.76924544
A39: Z11 | B39: S13 | C39: =IF(SQRT((Coordenadas!$C$12-Coordenadas!$C$156)^2+(Coordenadas!$D$12-Coordenadas!$D$156)^2)<=LEEME!$B$20,EXP(-LEEME!$B$19*SQRT((Coordenadas!$C$12-Coordenadas!$C$156)^2+(Coordenadas!$D$12-Coordenadas!$D$156)^2)),0) -> 0.56412879
A40: Z12 | B40: S2 | C40: =IF(SQRT((Coordenadas!$C$13-Coordenadas!$C$145)^2+(Coordenadas!$D$13-Coordenadas!$D$145)^2)<=LEEME!$B$20,EXP(-LEEME!$B$19*SQRT((Coordenadas!$C$13-Coordenadas!$C$145)^2+(Coordenadas!$D$13-Coordenadas!$D$145)^2)),0) -> 0.48081444
...

Sheet Alternativas
A1: alternativa | B1: material
A2: A1 | B2: plastico
A3: A2 | B3: plastico
A4: A3 | B4: papel_carton
A5: A4 | B5: plastico
A6: A5 | B6: plastico
A7: A6 | B7: plastico
A8: A7 | B8: plastico
A9: A8 | B9: plastico
A10: A9 | B10: plastico
A11: A10 | B11: plastico
A12: A11 | B12: plastico
... A51: A40 | B51: plastico

Sheet AtractivoAlternativas
A1: sector | B1: alternativa | C1: atractivo [-]
A2: Z1 | B2: A14 | C2: =IF(SQRT((Coordenadas!$C$2-Coordenadas!$C$177)^2+(Coordenadas!$D$2-Coordenadas!$D$177)^2)<=LEEME!$B$20,EXP(-LEEME!$B$19*SQRT((Coordenadas!$C$2-Coordenadas!$C$177)^2+(Coordenadas!$D$2-Coordenadas!$D$177)^2)),0) -> 0.74900702
A3: Z1 | B3: A17 | C3: =IF(SQRT((Coordenadas!$C$2-Coordenadas!$C$180)^2+(Coordenadas!$D$2-Coordenadas!$D$180)^2)<=LEEME!$B$20,EXP(-LEEME!$B$19*SQRT((Coordenadas!$C$2-Coordenadas!$C$180)^2+(Coordenadas!$D$2-Coordenadas!$D$180)^2)),0) -> 0.47976658
A4: Z1 | B4: A18 | C4: =IF(SQRT((Coordenadas!$C$2-Coordenadas!$C$181)^2+(Coordenadas!$D$2-Coordenadas!$D$181)^2)<=LEEME!$B$20,EXP(-LEEME!$B$19*SQRT((Coordenadas!$C$2-Coordenadas!$C$181)^2+(Coordenadas!$D$2-Coordenadas!$D$181)^2)),0) -> 0.87363504
A5: Z1 | B5: A19 | C5: =IF(SQRT((Coordenadas!$C$2-Coordenadas!$C$182)^2+(Coordenadas!$D$2-Coordenadas!$D$182)^2)<=LEEME!$B$20,EXP(-LEEME!$B$19*SQRT((Coordenadas!$C$2-Coordenadas!$C$182)^2+(Coordenadas!$D$2-Coordenadas!$D$182)^2)),0) -> 0.42075364
A6: Z1 | B6: A20 | C6: =IF(SQRT((Coordenadas!$C$2-Coordenadas!$C$183)^2+(Coordenadas!$D$2-Coordenadas!$D$183)^2)<=LEEME!$B$20,EXP(-LEEME!$B$19*SQRT((Coordenadas!$C$2-Coordenadas!$C$183)^2+(Coordenadas!$D$2-Coordenadas!$D$183)^2)),0) -> 0.40252422
A7: Z1 | B7: A25 | C7: =IF(SQRT((Coordenadas!$C$2-Coordenadas!$C$188)^2+(Coordenadas!$D$2-Coordenadas!$D$188)^2)<=LEEME!$B$20,EXP(-LEEME!$B$19*SQRT((Coordenadas!$C$2-Coordenadas!$C$188)^2+(Coordenadas!$D$2-Coordenadas!$D$188)^2)),0) -> 0.55997078
A8: Z1 | B8: A26 | C8: =IF(SQRT((Coordenadas!$C$2-Coordenadas!$C$189)^2+(Coordenadas!$D$2-Coordenadas!$D$189)^2)<=LEEME!$B$20,EXP(-LEEME!$B$19*SQRT((Coordenadas!$C$2-Coordenadas!$C$189)^2+(Coordenadas!$D$2-Coordenadas!$D$189)^2)),0) -> 0.4656383
A9: Z1 | B9: A27 | C9: =IF(SQRT((Coordenadas!$C$2-Coordenadas!$C$190)^2+(Coordenadas!$D$2-Coordenadas!$D$190)^2)<=LEEME!$B$20,EXP(-LEEME!$B$19*SQRT((Coordenadas!$C$2-Coordenadas!$C$190)^2+(Coordenadas!$D$2-Coordenadas!$D$190)^2)),0) -> 0.53254954
A10: Z2 | B10: A14 | C10: =IF(SQRT((Coordenadas!$C$3-Coordenadas!$C$177)^2+(Coordenadas!$D$3-Coordenadas!$D$177)^2)<=LEEME!$B$20,EXP(-LEEME!$B$19*SQRT((Coordenadas!$C$3-Coordenadas!$C$177)^2+(Coordenadas!$D$3-Coordenadas!$D$177)^2)),0) -> 0.66026074
A11: Z2 | B11: A17 | C11: =IF(SQRT((Coordenadas!$C$3-Coordenadas!$C$180)^2+(Coordenadas!$D$3-Coordenadas!$D$180)^2)<=LEEME!$B$20,EXP(-LEEME!$B$19*SQRT((Coordenadas!$C$3-Coordenadas!$C$180)^2+(Coordenadas!$D$3-Coordenadas!$D$180)^2)),0) -> 0.4100971
A12: Z2 | B12: A18 | C12: =IF(SQRT((Coordenadas!$C$3-Coordenadas!$C$181)^2+(Coordenadas!$D$3-Coordenadas!$D$181)^2)<=LEEME!$B$20,EXP(-LEEME!$B$19*SQRT((Coordenadas!$C$3-Coordenadas!$C$181)^2+(Coordenadas!$D$3-Coordenadas!$D$181)^2)),0) -> 0.76716977
A13: Z2 | B13: A19 | C13: =IF(SQRT((Coordenadas!$C$3-Coordenadas!$C$182)^2+(Coordenadas!$D$3-Coordenadas!$D$182)^2)<=LEEME!$B$20,EXP(-LEEME!$B$19*SQRT((Coordenadas!$C$3-Coordenadas!$C$182)^2+(Coordenadas!$D$3-Coordenadas!$D$182)^2)),0) -> 0.45611244
A14: Z2 | B14: A20 | C14: =IF(SQRT((Coordenadas!$C$3-Coordenadas!$C$183)^2+(Coordenadas!$D$3-Coordenadas!$D$183)^2)<=LEEME!$B$20,EXP(-LEEME!$B$19*SQRT((Coordenadas!$C$3-Coordenadas!$C$183)^2+(Coordenadas!$D$3-Coordenadas!$D$183)^2)),0) -> 0.44043165
A15: Z2 | B15: A25 | C15: =IF(SQRT((Coordenadas!$C$3-Coordenadas!$C$188)^2+(Coordenadas!$D$3-Coordenadas!$D$188)^2)<=LEEME!$B$20,EXP(-LEEME!$B$19*SQRT((Coordenadas!$C$3-Coordenadas!$C$188)^2+(Coordenadas!$D$3-Coordenadas!$D$188)^2)),0) -> 0.56485683
A16: Z2 | B16: A26 | C16: =IF(SQRT((Coordenadas!$C$3-Coordenadas!$C$189)^2+(Coordenadas!$D$3-Coordenadas!$D$189)^2)<=LEEME!$B$20,EXP(-LEEME!$B$19*SQRT((Coordenadas!$C$3-Coordenadas!$C$189)^2+(Coordenadas!$D$3-Coordenadas!$D$189)^2)),0) -> 0.5616312
A17: Z2 | B17: A27 | C17: =IF(SQRT((Coordenadas!$C$3-Coordenadas!$C$190)^2+(Coordenadas!$D$3-Coordenadas!$D$190)^2)<=LEEME!$B$20,EXP(-LEEME!$B$19*SQRT((Coordenadas!$C$3-Coordenadas!$C$190)^2+(Coordenadas!$D$3-Coordenadas!$D$190)^2)),0) -> 0.62767972
A18: Z3 | B18: A14 | C18: =IF(SQRT((Coordenadas!$C$4-Coordenadas!$C$177)^2+(Coordenadas!$D$4-Coordenadas!$D$177)^2)<=LEEME!$B$20,EXP(-LEEME!$B$19*SQRT((Coordenadas!$C$4-Coordenadas!$C$177)^2+(Coordenadas!$D$4-Coordenadas!$D$177)^2)),0) -> 0.4500816
A19: Z3 | B19: A17 | C19: =IF(SQRT((Coordenadas!$C$4-Coordenadas!$C$180)^2+(Coordenadas!$D$4-Coordenadas!$D$180)^2)<=LEEME!$B$20,EXP(-LEEME!$B$19*SQRT((Coordenadas!$C$4-Coordenadas!$C$180)^2+(Coordenadas!$D$4-Coordenadas!$D$180)^2)),0) -> 0.6791297
A20: Z3 | B20: A18 | C20: =IF(SQRT((Coordenadas!$C$4-Coordenadas!$C$181)^2+(Coordenadas!$D$4-Coordenadas!$D$181)^2)<=LEEME!$B$20,EXP(-LEEME!$B$19*SQRT((Coordenadas!$C$4-Coordenadas!$C$181)^2+(Coordenadas!$D$4-Coordenadas!$D$181)^2)),0) -> 0.51188049
A21: Z3 | B21: A22 | C21: =IF(SQRT((Coordenadas!$C$4-Coordenadas!$C$185)^2+(Coordenadas!$D$4-Coordenadas!$D$185)^2)<=LEEME!$B$20,EXP(-LEEME!$B$19*SQRT((Coordenadas!$C$4-Coordenadas!$C$185)^2+(Coordenadas!$D$4-Coordenadas!$D$185)^2)),0) -> 0.62188506
A22: Z3 | B22: A23 | C22: =IF(SQRT((Coordenadas!$C$4-Coordenadas!$C$186)^2+(Coordenadas!$D$4-Coordenadas!$D$186)^2)<=LEEME!$B$20,EXP(-LEEME!$B$19*SQRT((Coordenadas!$C$4-Coordenadas!$C$186)^2+(Coordenadas!$D$4-Coordenadas!$D$186)^2)),0) -> 0.37100987
A23: Z3 | B23: A25 | C23: =IF(SQRT((Coordenadas!$C$4-Coordenadas!$C$188)^2+(Coordenadas!$D$4-Coordenadas!$D$188)^2)<=LEEME!$B$20,EXP(-LEEME!$B$19*SQRT((Coordenadas!$C$4-Coordenadas!$C$188)^2+(Coordenadas!$D$4-Coordenadas!$D$188)^2)),0) -> 0.78330472
A24: Z3 | B24: A27 | C24: =IF(SQRT((Coordenadas!$C$4-Coordenadas!$C$190)^2+(Coordenadas!$D$4-Coordenadas!$D$190)^2)<=LEEME!$B$20,EXP(-LEEME!$B$19*SQRT((Coordenadas!$C$4-Coordenadas!$C$190)^2+(Coordenadas!$D$4-Coordenadas!$D$190)^2)),0) -> 0.51033842
A25: Z3 | B25: A30 | C25: =IF(SQRT((Coordenadas!$C$4-Coordenadas!$C$193)^2+(Coordenadas!$D$4-Coordenadas!$D$193)^2)<=LEEME!$B$20,EXP(-LEEME!$B$19*SQRT((Coordenadas!$C$4-Coordenadas!$C$193)^2+(Coordenadas!$D$4-Coordenadas!$D$193)^2)),0) -> 0.45605434
A26: Z4 | B26: A14 | C26: =IF(SQRT((Coordenadas!$C$5-Coordenadas!$C$177)^2+(Coordenadas!$D$5-Coordenadas!$D$177)^2)<=LEEME!$B$20,EXP(-LEEME!$B$19*SQRT((Coordenadas!$C$5-Coordenadas!$C$177)^2+(Coordenadas!$D$5-Coordenadas!$D$177)^2)),0) -> 0.61206456
A27: Z4 | B27: A17 | C27: =IF(SQRT((Coordenadas!$C$5-Coordenadas!$C$180)^2+(Coordenadas!$D$5-Coordenadas!$D$180)^2)<=LEEME!$B$20,EXP(-LEEME!$B$19*SQRT((Coordenadas!$C$5-Coordenadas!$C$180)^2+(Coordenadas!$D$5-Coordenadas!$D$180)^2)),0) -> 0.59506435
A28: Z4 | B28: A18 | C28: =IF(SQRT((Coordenadas!$C$5-Coordenadas!$C$181)^2+(Coordenadas!$D$5-Coordenadas!$D$181)^2)<=LEEME!$B$20,EXP(-LEEME!$B$19*SQRT((Coordenadas!$C$5-Coordenadas!$C$181)^2+(Coordenadas!$D$5-Coordenadas!$D$181)^2)),0) -> 0.69610838
A29: Z4 | B29: A22 | C29: =IF(SQRT((Coordenadas!$C$5-Coordenadas!$C$185)^2+(Coordenadas!$D$5-Coordenadas!$D$185)^2)<=LEEME!$B$20,EXP(-LEEME!$B$19*SQRT((Coordenadas!$C$5-Coordenadas!$C$185)^2+(Coordenadas!$D$5-Coordenadas!$D$185)^2)),0) -> 0.46628661
A30: Z4 | B30: A25 | C30: =IF(SQRT((Coordenadas!$C$5-Coordenadas!$C$188)^2+(Coordenadas!$D$5-Coordenadas!$D$188)^2)<=LEEME!$B$20,EXP(-LEEME!$B$19*SQRT((Coordenadas!$C$5-Coordenadas!$C$188)^2+(Coordenadas!$D$5-Coordenadas!$D$188)^2)),0) -> 0.66566382
A31: Z4 | B31: A26 | C31: =IF(SQRT((Coordenadas!$C$5-Coordenadas!$C$189)^2+(Coordenadas!$D$5-Coordenadas!$D$189)^2)<=LEEME!$B$20,EXP(-LEEME!$B$19*SQRT((Coordenadas!$C$5-Coordenadas!$C$189)^2+(Coordenadas!$D$5-Coordenadas!$D$189)^2)),0) -> 0.38733224
A32: Z4 | B32: A27 | C32: =IF(SQRT((Coordenadas!$C$5-Coordenadas!$C$190)^2+(Coordenadas!$D$5-Coordenadas!$D$190)^2)<=LEEME!$B$20,EXP(-LEEME!$B$19*SQRT((Coordenadas!$C$5-Coordenadas!$C$190)^2+(Coordenadas!$D$5-Coordenadas!$D$190)^2)),0) -> 0.53182183
A33: Z4 | B33: A30 | C33: =IF(SQRT((Coordenadas!$C$5-Coordenadas!$C$193)^2+(Coordenadas!$D$5-Coordenadas!$D$193)^2)<=LEEME!$B$20,EXP(-LEEME!$B$19*SQRT((Coordenadas!$C$5-Coordenadas!$C$193)^2+(Coordenadas!$D$5-Coordenadas!$D$193)^2)),0) -> 0.37931278
A34: Z5 | B34: A14 | C34: =IF(SQRT((Coordenadas!$C$6-Coordenadas!$C$177)^2+(Coordenadas!$D$6-Coordenadas!$D$177)^2)<=LEEME!$B$20,EXP(-LEEME!$B$19*SQRT((Coordenadas!$C$6-Coordenadas!$C$177)^2+(Coordenadas!$D$6-Coordenadas!$D$177)^2)),0) -> 0.5499007
A35: Z5 | B35: A17 | C35: =IF(SQRT((Coordenadas!$C$6-Coordenadas!$C$180)^2+(Coordenadas!$D$6-Coordenadas!$D$180)^2)<=LEEME!$B$20,EXP(-LEEME!$B$19*SQRT((Coordenadas!$C$6-Coordenadas!$C$180)^2+(Coordenadas!$D$6-Coordenadas!$D$180)^2)),0) -> 0.5460293
A36: Z5 | B36: A18 | C36: =IF(SQRT((Coordenadas!$C$6-Coordenadas!$C$181)^2+(Coordenadas!$D$6-Coordenadas!$D$181)^2)<=LEEME!$B$20,EXP(-LEEME!$B$19*SQRT((Coordenadas!$C$6-Coordenadas!$C$181)^2+(Coordenadas!$D$6-Coordenadas!$D$181)^2)),0) -> 0.63994421
A37: Z5 | B37: A22 | C37: =IF(SQRT((Coordenadas!$C$6-Coordenadas!$C$185)^2+(Coordenadas!$D$6-Coordenadas!$D$185)^2)<=LEEME!$B$20,EXP(-LEEME!$B$19*SQRT((Coordenadas!$C$6-Coordenadas!$C$185)^2+(Coordenadas!$D$6-Coordenadas!$D$185)^2)),0) -> 0.46973067
A38: Z5 | B38: A25 | C38: =IF(SQRT((Coordenadas!$C$6-Coordenadas!$C$188)^2+(Coordenadas!$D$6-Coordenadas!$D$188)^2)<=LEEME!$B$20,EXP(-LEEME!$B$19*SQRT((Coordenadas!$C$6-Coordenadas!$C$188)^2+(Coordenadas!$D$6-Coordenadas!$D$188)^2)),0) -> 0.76430099
A39: Z5 | B39: A26 | C39: =IF(SQRT((Coordenadas!$C$6-Coordenadas!$C$189)^2+(Coordenadas!$D$6-Coordenadas!$D$189)^2)<=LEEME!$B$20,EXP(-LEEME!$B$19*SQRT((Coordenadas!$C$6-Coordenadas!$C$189)^2+(Coordenadas!$D$6-Coordenadas!$D$189)^2)),0) -> 0.41255102
A40: Z5 | B40: A27 | C40: =IF(SQRT((Coordenadas!$C$6-Coordenadas!$C$190)^2+(Coordenadas!$D$6-Coordenadas!$D$190)^2)<=LEEME!$B$20,EXP(-LEEME!$B$19*SQRT((Coordenadas!$C$6-Coordenadas!$C$190)^2+(Coordenadas!$D$6-Coordenadas!$D$190)^2)),0) -> 0.62242584
...

Sheet Camiones
A1: camion | B1: capacidad [ton/recorrido] | C1: costo_recorrido [CLP/recorrido] | D1: volumen [m3/recorrido] | E1: compatible_campana [0/1]
A2: H1 | B2: 1.5 | C2: 222000 | D2: 5.5 | E2: 1
A3: H2 | B3: 2.4 | C3: 287000 | D3: 8.8 | E3: 1
A4: H3 | B4: 4 | C4: 384000 | D4: 20.8 | E4: 1

Sheet Costos
A1: parametro | B1: valor | C1: unidad
A2: F | B2: 10 | C2: visitas/semana
A3: B | B3: 180000000 | C3: CLP/año
A4: cH | B4: 36000000 | C4: CLP/ubicación habilitada
A5: tasa_mantencion | B5: 0.05 | C5: 1/año

Sheet Calibracion
A1: sector | B1: poblacion [hab] | C1: generación g_im [ton/hab/año] | H1: atractivo alternativas que reciben m [-] | M1: atractivo puntos actuales u_in [-] | T1: suma puntos actuales [-] | U1: captura por unidad de atractivo [ton/hab/año] | AA1: Calibración de uN por material. Buscar objetivo, una vez por material: definir la celda de la fila 18 = 0 cambiando el uN de la fila 4.
C2: papel_carton | D2: plastico | E2: vidrio | F2: metal | G2: carton_liquidos | H2: papel_carton | I2: plastico | J2: vidrio | K2: metal | L2: carton_liquidos | M2: S1 | N2: S2 | O2: S3 | P2: S4 | Q2: S5 | R2: S6 | S2: S7 | U2: papel_carton | V2: plastico | W2: vidrio | X2: metal | Y2: carton_liquidos
A3: Z1 | B3: =SUMIFS(Sectores!$C:$C,Sectores!$A:$A,$A3) -> 2849 | C3: =SUMIFS(Generacion!$C:$C,Generacion!$A:$A,$A3,Generacion!$B:$B,C$2) -> 0.043533877 | D3: =SUMIFS(Generacion!$C:$C,Generacion!$A:$A,$A3,Generacion!$B:$B,D$2) -> 0.037870933 | E3: =SUMIFS(Generacion!$C:$C,Generacion!$A:$A,$A3,Generacion!$B:$B,E$2) -> 0.01344949 | F3: =SUMIFS(Generacion!$C:$C,Generacion!$A:$A,$A3,Generacion!$B:$B,F$2) -> 0.0035393396 | G3: =SUMIFS(Generacion!$C:$C,Generacion!$A:$A,$A3,Generacion!$B:$B,G$2) -> 0.0024775377 | H3: =SUMPRODUCT((AtractivoAlternativas!$A$2:$A$931=$A3)*AtractivoAlternativas!$C$2:$C$931*COUNTIFS(Alternativas!$A$2:$A$51,AtractivoAlternativas!$B$2:$B$931,Alternativas!$B$2:$B$51,H$2)) -> 1.2146453 | I3: =SUMPRODUCT((AtractivoAlternativas!$A$2:$A$931=$A3)*AtractivoAlternativas!$C$2:$C$931*COUNTIFS(Alternativas!$A$2:$A$51,AtractivoAlternativas!$B$2:$B$931,Alternativas!$B$2:$B$51,I$2)) -> 3.3323139 | J3: =SUMPRODUCT((AtractivoAlternativas!$A$2:$A$931=$A3)*AtractivoAlternativas!$C$2:$C$931*COUNTIFS(Alternativas!$A$2:$A$51,AtractivoAlternativas!$B$2:$B$931,Alternativas!$B$2:$B$51,J$2)) -> 2.1497191 | K3: =SUMPRODUCT((AtractivoAlternativas!$A$2:$A$931=$A3)*AtractivoAlternativas!$C$2:$C$931*COUNTIFS(Alternativas!$A$2:$A$51,AtractivoAlternativas!$B$2:$B$931,Alternativas!$B$2:$B$51,K$2)) -> 0 | L3: =SUMPRODUCT((AtractivoAlternativas!$A$2:$A$931=$A3)*AtractivoAlternativas!$C$2:$C$931*COUNTIFS(Alternativas!$A$2:$A$51,AtractivoAlternativas!$B$2:$B$931,Alternativas!$B$2:$B$51,L$2)) -> 0 | M3: =SUMIFS(AtractivoSitios!$C:$C,AtractivoSitios!$A:$A,$A3,AtractivoSitios!$B:$B,M$2) -> 0 | N3: =SUMIFS(AtractivoSitios!$C:$C,AtractivoSitios!$A:$A,$A3,AtractivoSitios!$B:$B,N$2) -> 0 | O3: =SUMIFS(AtractivoSitios!$C:$C,AtractivoSitios!$A:$A,$A3,AtractivoSitios!$B:$B,O$2) -> 0 | P3: =SUMIFS(AtractivoSitios!$C:$C,AtractivoSitios!$A:$A,$A3,AtractivoSitios!$B:$B,P$2) -> 0 | Q3: =SUMIFS(AtractivoSitios!$C:$C,AtractivoSitios!$A:$A,$A3,AtractivoSitios!$B:$B,Q$2) -> 0 | R3: =SUMIFS(AtractivoSitios!$C:$C,AtractivoSitios!$A:$A,$A3,AtractivoSitios!$B:$B,R$2) -> 0 | S3: =SUMIFS(AtractivoSitios!$C:$C,AtractivoSitios!$A:$A,$A3,AtractivoSitios!$B:$B,S$2) -> 0 | T3: =SUM(M3:S3) -> 0 | U3: =C3/(AD$4+H3+$T3) -> 0.00019212852 | V3: =D3/(AE$4+I3+$T3) -> 5.5437853e-05 | W3: =E3/(AF$4+J3+$T3) -> 0.00031217797 | X3: =F3/(AG$4+K3+$T3) -> 1.7469273e-05 | Y3: =G3/(AH$4+L3+$T3) -> 1.083362e-05 | AC3: material | AD3: papel_carton | AE3: plastico | AF3: vidrio | AG3: metal | AH3: carton_liquidos
A4: Z2 | B4: =SUMIFS(Sectores!$C:$C,Sectores!$A:$A,$A4) -> 5671 | C4: =SUMIFS(Generacion!$C:$C,Generacion!$A:$A,$A4,Generacion!$B:$B,C$2) -> 0.043533877 | D4: =SUMIFS(Generacion!$C:$C,Generacion!$A:$A,$A4,Generacion!$B:$B,D$2) -> 0.037870933 | E4: =SUMIFS(Generacion!$C:$C,Generacion!$A:$A,$A4,Generacion!$B:$B,E$2) -> 0.01344949 | F4: =SUMIFS(Generacion!$C:$C,Generacion!$A:$A,$A4,Generacion!$B:$B,F$2) -> 0.0035393396 | G4: =SUMIFS(Generacion!$C:$C,Generacion!$A:$A,$A4,Generacion!$B:$B,G$2) -> 0.0024775377 | H4: =SUMPRODUCT((AtractivoAlternativas!$A$2:$A$931=$A4)*AtractivoAlternativas!$C$2:$C$931*COUNTIFS(Alternativas!$A$2:$A$51,AtractivoAlternativas!$B$2:$B$931,Alternativas!$B$2:$B$51,H$2)) -> 1.2218919 | I4: =SUMPRODUCT((AtractivoAlternativas!$A$2:$A$931=$A4)*AtractivoAlternativas!$C$2:$C$931*COUNTIFS(Alternativas!$A$2:$A$51,AtractivoAlternativas!$B$2:$B$931,Alternativas!$B$2:$B$51,I$2)) -> 3.3875471 | J4: =SUMPRODUCT((AtractivoAlternativas!$A$2:$A$931=$A4)*AtractivoAlternativas!$C$2:$C$931*COUNTIFS(Alternativas!$A$2:$A$51,AtractivoAlternativas!$B$2:$B$931,Alternativas!$B$2:$B$51,J$2)) -> 2.2900033 | K4: =SUMPRODUCT((AtractivoAlternativas!$A$2:$A$931=$A4)*AtractivoAlternativas!$C$2:$C$931*COUNTIFS(Alternativas!$A$2:$A$51,AtractivoAlternativas!$B$2:$B$931,Alternativas!$B$2:$B$51,K$2)) -> 0 | L4: =SUMPRODUCT((AtractivoAlternativas!$A$2:$A$931=$A4)*AtractivoAlternativas!$C$2:$C$931*COUNTIFS(Alternativas!$A$2:$A$51,AtractivoAlternativas!$B$2:$B$931,Alternativas!$B$2:$B$51,L$2)) -> 0 | M4: =SUMIFS(AtractivoSitios!$C:$C,AtractivoSitios!$A:$A,$A4,AtractivoSitios!$B:$B,M$2) -> 0 | N4: =SUMIFS(AtractivoSitios!$C:$C,AtractivoSitios!$A:$A,$A4,AtractivoSitios!$B:$B,N$2) -> 0 | O4: =SUMIFS(AtractivoSitios!$C:$C,AtractivoSitios!$A:$A,$A4,AtractivoSitios!$B:$B,O$2) -> 0 | P4: =SUMIFS(AtractivoSitios!$C:$C,AtractivoSitios!$A:$A,$A4,AtractivoSitios!$B:$B,P$2) -> 0 | Q4: =SUMIFS(AtractivoSitios!$C:$C,AtractivoSitios!$A:$A,$A4,AtractivoSitios!$B:$B,Q$2) -> 0 | R4: =SUMIFS(AtractivoSitios!$C:$C,AtractivoSitios!$A:$A,$A4,AtractivoSitios!$B:$B,R$2) -> 0 | S4: =SUMIFS(AtractivoSitios!$C:$C,AtractivoSitios!$A:$A,$A4,AtractivoSitios!$B:$B,S$2) -> 0 | T4: =SUM(M4:S4) -> 0 | U4: =C4/(AD$4+H4+$T4) -> 0.00019212237 | V4: =D4/(AE$4+I4+$T4) -> 5.5433371e-05 | W4: =E4/(AF$4+J4+$T4) -> 0.00031116477 | X4: =F4/(AG$4+K4+$T4) -> 1.7469273e-05 | Y4: =G4/(AH$4+L4+$T4) -> 1.083362e-05 | AC4: uN [-] | AD4: 225.37263 | AE4: 679.79179 | AF4: 40.933046 | AG4: 202.60371 | AH4: 228.68973
A5: Z3 | B5: =SUMIFS(Sectores!$C:$C,Sectores!$A:$A,$A5) -> 2170 | C5: =SUMIFS(Generacion!$C:$C,Generacion!$A:$A,$A5,Generacion!$B:$B,C$2) -> 0.043533877 | D5: =SUMIFS(Generacion!$C:$C,Generacion!$A:$A,$A5,Generacion!$B:$B,D$2) -> 0.037870933 | E5: =SUMIFS(Generacion!$C:$C,Generacion!$A:$A,$A5,Generacion!$B:$B,E$2) -> 0.01344949 | F5: =SUMIFS(Generacion!$C:$C,Generacion!$A:$A,$A5,Generacion!$B:$B,F$2) -> 0.0035393396 | G5: =SUMIFS(Generacion!$C:$C,Generacion!$A:$A,$A5,Generacion!$B:$B,G$2) -> 0.0024775377 | H5: =SUMPRODUCT((AtractivoAlternativas!$A$2:$A$931=$A5)*AtractivoAlternativas!$C$2:$C$931*COUNTIFS(Alternativas!$A$2:$A$51,AtractivoAlternativas!$B$2:$B$931,Alternativas!$B$2:$B$51,H$2)) -> 1.528021 | I5: =SUMPRODUCT((AtractivoAlternativas!$A$2:$A$931=$A5)*AtractivoAlternativas!$C$2:$C$931*COUNTIFS(Alternativas!$A$2:$A$51,AtractivoAlternativas!$B$2:$B$931,Alternativas!$B$2:$B$51,I$2)) -> 3.4775483 | J5: =SUMPRODUCT((AtractivoAlternativas!$A$2:$A$931=$A5)*AtractivoAlternativas!$C$2:$C$931*COUNTIFS(Alternativas!$A$2:$A$51,AtractivoAlternativas!$B$2:$B$931,Alternativas!$B$2:$B$51,J$2)) -> 0.96042002 | K5: =SUMPRODUCT((AtractivoAlternativas!$A$2:$A$931=$A5)*AtractivoAlternativas!$C$2:$C$931*COUNTIFS(Alternativas!$A$2:$A$51,AtractivoAlternativas!$B$2:$B$931,Alternativas!$B$2:$B$51,K$2)) -> 0 | L5: =SUMPRODUCT((AtractivoAlternativas!$A$2:$A$931=$A5)*AtractivoAlternativas!$C$2:$C$931*COUNTIFS(Alternativas!$A$2:$A$51,AtractivoAlternativas!$B$2:$B$931,Alternativas!$B$2:$B$51,L$2)) -> 0 | M5: =SUMIFS(AtractivoSitios!$C:$C,AtractivoSitios!$A:$A,$A5,AtractivoSitios!$B:$B,M$2) -> 0.48153799 | N5: =SUMIFS(AtractivoSitios!$C:$C,AtractivoSitios!$A:$A,$A5,AtractivoSitios!$B:$B,N$2) -> 0 | O5: =SUMIFS(AtractivoSitios!$C:$C,AtractivoSitios!$A:$A,$A5,AtractivoSitios!$B:$B,O$2) -> 0 | P5: =SUMIFS(AtractivoSitios!$C:$C,AtractivoSitios!$A:$A,$A5,AtractivoSitios!$B:$B,P$2) -> 0 | Q5: =SUMIFS(AtractivoSitios!$C:$C,AtractivoSitios!$A:$A,$A5,AtractivoSitios!$B:$B,Q$2) -> 0 | R5: =SUMIFS(AtractivoSitios!$C:$C,AtractivoSitios!$A:$A,$A5,AtractivoSitios!$B:$B,R$2) -> 0 | S5: =SUMIFS(AtractivoSitios!$C:$C,AtractivoSitios!$A:$A,$A5,AtractivoSitios!$B:$B,S$2) -> 0 | T5: =SUM(M5:S5) -> 0.48153799 | U5: =C5/(AD$4+H5+$T5) -> 0.00019145685 | V5: =D5/(AE$4+I5+$T5) -> 5.5387035e-05 | W5: =E5/(AF$4+J5+$T5) -> 0.00031739207 | X5: =F5/(AG$4+K5+$T5) -> 1.7427852e-05 | Y5: =G5/(AH$4+L5+$T5) -> 1.0810857e-05
A6: Z4 | B6: =SUMIFS(Sectores!$C:$C,Sectores!$A:$A,$A6) -> 1868 | C6: =SUMIFS(Generacion!$C:$C,Generacion!$A:$A,$A6,Generacion!$B:$B,C$2) -> 0.043533877 | D6: =SUMIFS(Generacion!$C:$C,Generacion!$A:$A,$A6,Generacion!$B:$B,D$2) -> 0.037870933 | E6: =SUMIFS(Generacion!$C:$C,Generacion!$A:$A,$A6,Generacion!$B:$B,E$2) -> 0.01344949 | F6: =SUMIFS(Generacion!$C:$C,Generacion!$A:$A,$A6,Generacion!$B:$B,F$2) -> 0.0035393396 | G6: =SUMIFS(Generacion!$C:$C,Generacion!$A:$A,$A6,Generacion!$B:$B,G$2) -> 0.0024775377 | H6: =SUMPRODUCT((AtractivoAlternativas!$A$2:$A$931=$A6)*AtractivoAlternativas!$C$2:$C$931*COUNTIFS(Alternativas!$A$2:$A$51,AtractivoAlternativas!$B$2:$B$931,Alternativas!$B$2:$B$51,H$2)) -> 1.8449962 | I6: =SUMPRODUCT((AtractivoAlternativas!$A$2:$A$931=$A6)*AtractivoAlternativas!$C$2:$C$931*COUNTIFS(Alternativas!$A$2:$A$51,AtractivoAlternativas!$B$2:$B$931,Alternativas!$B$2:$B$51,I$2)) -> 3.3422772 | J6: =SUMPRODUCT((AtractivoAlternativas!$A$2:$A$931=$A6)*AtractivoAlternativas!$C$2:$C$931*COUNTIFS(Alternativas!$A$2:$A$51,AtractivoAlternativas!$B$2:$B$931,Alternativas!$B$2:$B$51,J$2)) -> 1.5312186 | K6: =SUMPRODUCT((AtractivoAlternativas!$A$2:$A$931=$A6)*AtractivoAlternativas!$C$2:$C$931*COUNTIFS(Alternativas!$A$2:$A$51,AtractivoAlternativas!$B$2:$B$931,Alternativas!$B$2:$B$51,K$2)) -> 0 | L6: =SUMPRODUCT((AtractivoAlternativas!$A$2:$A$931=$A6)*AtractivoAlternativas!$C$2:$C$931*COUNTIFS(Alternativas!$A$2:$A$51,AtractivoAlternativas!$B$2:$B$931,Alternativas!$B$2:$B$51,L$2)) -> 0 | M6: =SUMIFS(AtractivoSitios!$C:$C,AtractivoSitios!$A:$A,$A6,AtractivoSitios!$B:$B,M$2) -> 0.3827932 | N6: =SUMIFS(AtractivoSitios!$C:$C,AtractivoSitios!$A:$A,$A6,AtractivoSitios!$B:$B,N$2) -> 0 | O6: =SUMIFS(AtractivoSitios!$C:$C,AtractivoSitios!$A:$A,$A6,AtractivoSitios!$B:$B,O$2) -> 0 | P6: =SUMIFS(AtractivoSitios!$C:$C,AtractivoSitios!$A:$A,$A6,AtractivoSitios!$B:$B,P$2) -> 0 | Q6: =SUMIFS(AtractivoSitios!$C:$C,AtractivoSitios!$A:$A,$A6,AtractivoSitios!$B:$B,Q$2) -> 0 | R6: =SUMIFS(AtractivoSitios!$C:$C,AtractivoSitios!$A:$A,$A6,AtractivoSitios!$B:$B,R$2) -> 0 | S6: =SUMIFS(AtractivoSitios!$C:$C,AtractivoSitios!$A:$A,$A6,AtractivoSitios!$B:$B,S$2) -> 0 | T6: =SUM(M6:S6) -> 0.3827932 | U6: =C6/(AD$4+H6+$T6) -> 0.00019127328 | V6: =D6/(AE$4+I6+$T6) -> 5.5405998e-05 | W6: =E6/(AF$4+J6+$T6) -> 0.0003138953 | X6: =F6/(AG$4+K6+$T6) -> 1.743633e-05 | Y6: =G6/(AH$4+L6+$T6) -> 1.0815517e-05 | AA6: punto | AB6: sitio | AC6: nombre | AD6: papel_carton modelo [ton/año] | AE6: plastico modelo [ton/año] | AF6: vidrio modelo [ton/año] | AG6: metal modelo [ton/año] | AH6: carton_liquidos modelo [ton/año] | AI6: total modelo [ton/año] | AJ6: total real 2023 [ton] | AK6: calibra [1/0] | AL6: error modelo − real [ton]
A7: Z5 | B7: =SUMIFS(Sectores!$C:$C,Sectores!$A:$A,$A7) -> 1511 | C7: =SUMIFS(Generacion!$C:$C,Generacion!$A:$A,$A7,Generacion!$B:$B,C$2) -> 0.043533877 | D7: =SUMIFS(Generacion!$C:$C,Generacion!$A:$A,$A7,Generacion!$B:$B,D$2) -> 0.037870933 | E7: =SUMIFS(Generacion!$C:$C,Generacion!$A:$A,$A7,Generacion!$B:$B,E$2) -> 0.01344949 | F7: =SUMIFS(Generacion!$C:$C,Generacion!$A:$A,$A7,Generacion!$B:$B,F$2) -> 0.0035393396 | G7: =SUMIFS(Generacion!$C:$C,Generacion!$A:$A,$A7,Generacion!$B:$B,G$2) -> 0.0024775377 | H7: =SUMPRODUCT((AtractivoAlternativas!$A$2:$A$931=$A7)*AtractivoAlternativas!$C$2:$C$931*COUNTIFS(Alternativas!$A$2:$A$51,AtractivoAlternativas!$B$2:$B$931,Alternativas!$B$2:$B$51,H$2)) -> 1.8767798 | I7: =SUMPRODUCT((AtractivoAlternativas!$A$2:$A$931=$A7)*AtractivoAlternativas!$C$2:$C$931*COUNTIFS(Alternativas!$A$2:$A$51,AtractivoAlternativas!$B$2:$B$931,Alternativas!$B$2:$B$51,I$2)) -> 3.454982 | J7: =SUMPRODUCT((AtractivoAlternativas!$A$2:$A$931=$A7)*AtractivoAlternativas!$C$2:$C$931*COUNTIFS(Alternativas!$A$2:$A$51,AtractivoAlternativas!$B$2:$B$931,Alternativas!$B$2:$B$51,J$2)) -> 1.5848776 | K7: =SUMPRODUCT((AtractivoAlternativas!$A$2:$A$931=$A7)*AtractivoAlternativas!$C$2:$C$931*COUNTIFS(Alternativas!$A$2:$A$51,AtractivoAlternativas!$B$2:$B$931,Alternativas!$B$2:$B$51,K$2)) -> 0 | L7: =SUMPRODUCT((AtractivoAlternativas!$A$2:$A$931=$A7)*AtractivoAlternativas!$C$2:$C$931*COUNTIFS(Alternativas!$A$2:$A$51,AtractivoAlternativas!$B$2:$B$931,Alternativas!$B$2:$B$51,L$2)) -> 0 | M7: =SUMIFS(AtractivoSitios!$C:$C,AtractivoSitios!$A:$A,$A7,AtractivoSitios!$B:$B,M$2) -> 0 | N7: =SUMIFS(AtractivoSitios!$C:$C,AtractivoSitios!$A:$A,$A7,AtractivoSitios!$B:$B,N$2) -> 0 | O7: =SUMIFS(AtractivoSitios!$C:$C,AtractivoSitios!$A:$A,$A7,AtractivoSitios!$B:$B,O$2) -> 0 | P7: =SUMIFS(AtractivoSitios!$C:$C,AtractivoSitios!$A:$A,$A7,AtractivoSitios!$B:$B,P$2) -> 0 | Q7: =SUMIFS(AtractivoSitios!$C:$C,AtractivoSitios!$A:$A,$A7,AtractivoSitios!$B:$B,Q$2) -> 0 | R7: =SUMIFS(AtractivoSitios!$C:$C,AtractivoSitios!$A:$A,$A7,AtractivoSitios!$B:$B,R$2) -> 0 | S7: =SUMIFS(AtractivoSitios!$C:$C,AtractivoSitios!$A:$A,$A7,AtractivoSitios!$B:$B,S$2) -> 0 | T7: =SUM(M7:S7) -> 0 | U7: =C7/(AD$4+H7+$T7) -> 0.00019156872 | V7: =D7/(AE$4+I7+$T7) -> 5.54279e-05 | W7: =E7/(AF$4+J7+$T7) -> 0.00031632519 | X7: =F7/(AG$4+K7+$T7) -> 1.7469273e-05 | Y7: =G7/(AH$4+L7+$T7) -> 1.083362e-05 | AA7: P1 | AB7: S1 | AC7: Juan de Dios Malebrán | AD7: =SUMPRODUCT($B$3:$B$144,U$3:U$144,M$3:M$144) -> 12.010602 | AE7: =SUMPRODUCT($B$3:$B$144,V$3:V$144,M$3:M$144) -> 3.4757058 | AF7: =SUMPRODUCT($B$3:$B$144,W$3:W$144,M$3:M$144) -> 19.830079 | AG7: =SUMPRODUCT($B$3:$B$144,X$3:X$144,M$3:M$144) -> 1.0920448 | AH7: =SUMPRODUCT($B$3:$B$144,Y$3:Y$144,M$3:M$144) -> 0.67760549 | AI7: =SUM(AD7:AH7) -> 37.086037 | AJ7: 51.6877 | AK7: 1 | AL7: =AI7-AJ7 -> -14.601663
A8: Z6 | B8: =SUMIFS(Sectores!$C:$C,Sectores!$A:$A,$A8) -> 3068 | C8: =SUMIFS(Generacion!$C:$C,Generacion!$A:$A,$A8,Generacion!$B:$B,C$2) -> 0.043533877 | D8: =SUMIFS(Generacion!$C:$C,Generacion!$A:$A,$A8,Generacion!$B:$B,D$2) -> 0.037870933 | E8: =SUMIFS(Generacion!$C:$C,Generacion!$A:$A,$A8,Generacion!$B:$B,E$2) -> 0.01344949 | F8: =SUMIFS(Generacion!$C:$C,Generacion!$A:$A,$A8,Generacion!$B:$B,F$2) -> 0.0035393396 | G8: =SUMIFS(Generacion!$C:$C,Generacion!$A:$A,$A8,Generacion!$B:$B,G$2) -> 0.0024775377 | H8: =SUMPRODUCT((AtractivoAlternativas!$A$2:$A$931=$A8)*AtractivoAlternativas!$C$2:$C$931*COUNTIFS(Alternativas!$A$2:$A$51,AtractivoAlternativas!$B$2:$B$931,Alternativas!$B$2:$B$51,H$2)) -> 1.3457005 | I8: =SUMPRODUCT((AtractivoAlternativas!$A$2:$A$931=$A8)*AtractivoAlternativas!$C$2:$C$931*COUNTIFS(Alternativas!$A$2:$A$51,AtractivoAlternativas!$B$2:$B$931,Alternativas!$B$2:$B$51,I$2)) -> 3.7203491 | J8: =SUMPRODUCT((AtractivoAlternativas!$A$2:$A$931=$A8)*AtractivoAlternativas!$C$2:$C$931*COUNTIFS(Alternativas!$A$2:$A$51,AtractivoAlternativas!$B$2:$B$931,Alternativas!$B$2:$B$51,J$2)) -> 2.3554696 | K8: =SUMPRODUCT((AtractivoAlternativas!$A$2:$A$931=$A8)*AtractivoAlternativas!$C$2:$C$931*COUNTIFS(Alternativas!$A$2:$A$51,AtractivoAlternativas!$B$2:$B$931,Alternativas!$B$2:$B$51,K$2)) -> 0 | L8: =SUMPRODUCT((AtractivoAlternativas!$A$2:$A$931=$A8)*AtractivoAlternativas!$C$2:$C$931*COUNTIFS(Alternativas!$A$2:$A$51,AtractivoAlternativas!$B$2:$B$931,Alternativas!$B$2:$B$51,L$2)) -> 0 | M8: =SUMIFS(AtractivoSitios!$C:$C,AtractivoSitios!$A:$A,$A8,AtractivoSitios!$B:$B,M$2) -> 0 | N8: =SUMIFS(AtractivoSitios!$C:$C,AtractivoSitios!$A:$A,$A8,AtractivoSitios!$B:$B,N$2) -> 0 | O8: =SUMIFS(AtractivoSitios!$C:$C,AtractivoSitios!$A:$A,$A8,AtractivoSitios!$B:$B,O$2) -> 0 | P8: =SUMIFS(AtractivoSitios!$C:$C,AtractivoSitios!$A:$A,$A8,AtractivoSitios!$B:$B,P$2) -> 0 | Q8: =SUMIFS(AtractivoSitios!$C:$C,AtractivoSitios!$A:$A,$A8,AtractivoSitios!$B:$B,Q$2) -> 0 | R8: =SUMIFS(AtractivoSitios!$C:$C,AtractivoSitios!$A:$A,$A8,AtractivoSitios!$B:$B,R$2) -> 0 | S8: =SUMIFS(AtractivoSitios!$C:$C,AtractivoSitios!$A:$A,$A8,AtractivoSitios!$B:$B,S$2) -> 0 | T8: =SUM(M8:S8) -> 0 | U8: =C8/(AD$4+H8+$T8) -> 0.00019201746 | V8: =D8/(AE$4+I8+$T8) -> 5.540638e-05 | W8: =E8/(AF$4+J8+$T8) -> 0.00031069419 | X8: =F8/(AG$4+K8+$T8) -> 1.7469273e-05 | Y8: =G8/(AH$4+L8+$T8) -> 1.083362e-05 | AA8: P2 | AB8: S2 | AC8: Los Toros | AD8: =SUMPRODUCT($B$3:$B$144,U$3:U$144,N$3:N$144) -> 10.089964 | AE8: =SUMPRODUCT($B$3:$B$144,V$3:V$144,N$3:N$144) -> 2.9129223 | AF8: =SUMPRODUCT($B$3:$B$144,W$3:W$144,N$3:N$144) -> 16.882196 | AG8: =SUMPRODUCT($B$3:$B$144,X$3:X$144,N$3:N$144) -> 0.912702 | AH8: =SUMPRODUCT($B$3:$B$144,Y$3:Y$144,N$3:N$144) -> 0.56627611 | AI8: =SUM(AD8:AH8) -> 31.36406 | AJ8: 48.8408 | AK8: 1 | AL8: =AI8-AJ8 -> -17.47674
A9: Z7 | B9: =SUMIFS(Sectores!$C:$C,Sectores!$A:$A,$A9) -> 3975 | C9: =SUMIFS(Generacion!$C:$C,Generacion!$A:$A,$A9,Generacion!$B:$B,C$2) -> 0.043533877 | D9: =SUMIFS(Generacion!$C:$C,Generacion!$A:$A,$A9,Generacion!$B:$B,D$2) -> 0.037870933 | E9: =SUMIFS(Generacion!$C:$C,Generacion!$A:$A,$A9,Generacion!$B:$B,E$2) -> 0.01344949 | F9: =SUMIFS(Generacion!$C:$C,Generacion!$A:$A,$A9,Generacion!$B:$B,F$2) -> 0.0035393396 | G9: =SUMIFS(Generacion!$C:$C,Generacion!$A:$A,$A9,Generacion!$B:$B,G$2) -> 0.0024775377 | H9: =SUMPRODUCT((AtractivoAlternativas!$A$2:$A$931=$A9)*AtractivoAlternativas!$C$2:$C$931*COUNTIFS(Alternativas!$A$2:$A$51,AtractivoAlternativas!$B$2:$B$931,Alternativas!$B$2:$B$51,H$2)) -> 0 | I9: =SUMPRODUCT((AtractivoAlternativas!$A$2:$A$931=$A9)*AtractivoAlternativas!$C$2:$C$931*COUNTIFS(Alternativas!$A$2:$A$51,AtractivoAlternativas!$B$2:$B$931,Alternativas!$B$2:$B$51,I$2)) -> 0.77012753 | J9: =SUMPRODUCT((AtractivoAlternativas!$A$2:$A$931=$A9)*AtractivoAlternativas!$C$2:$C$931*COUNTIFS(Alternativas!$A$2:$A$51,AtractivoAlternativas!$B$2:$B$931,Alternativas!$B$2:$B$51,J$2)) -> 0 | K9: =SUMPRODUCT((AtractivoAlternativas!$A$2:$A$931=$A9)*AtractivoAlternativas!$C$2:$C$931*COUNTIFS(Alternativas!$A$2:$A$51,AtractivoAlternativas!$B$2:$B$931,Alternativas!$B$2:$B$51,K$2)) -> 0 | L9: =SUMPRODUCT((AtractivoAlternativas!$A$2:$A$931=$A9)*AtractivoAlternativas!$C$2:$C$931*COUNTIFS(Alternativas!$A$2:$A$51,AtractivoAlternativas!$B$2:$B$931,Alternativas!$B$2:$B$51,L$2)) -> 0 | M9: =SUMIFS(AtractivoSitios!$C:$C,AtractivoSitios!$A:$A,$A9,AtractivoSitios!$B:$B,M$2) -> 0 | N9: =SUMIFS(AtractivoSitios!$C:$C,AtractivoSitios!$A:$A,$A9,AtractivoSitios!$B:$B,N$2) -> 0.37898048 | O9: =SUMIFS(AtractivoSitios!$C:$C,AtractivoSitios!$A:$A,$A9,AtractivoSitios!$B:$B,O$2) -> 0 | P9: =SUMIFS(AtractivoSitios!$C:$C,AtractivoSitios!$A:$A,$A9,AtractivoSitios!$B:$B,P$2) -> 0 | Q9: =SUMIFS(AtractivoSitios!$C:$C,AtractivoSitios!$A:$A,$A9,AtractivoSitios!$B:$B,Q$2) -> 0 | R9: =SUMIFS(AtractivoSitios!$C:$C,AtractivoSitios!$A:$A,$A9,AtractivoSitios!$B:$B,R$2) -> 0 | S9: =SUMIFS(AtractivoSitios!$C:$C,AtractivoSitios!$A:$A,$A9,AtractivoSitios!$B:$B,S$2) -> 0 | T9: =SUM(M9:S9) -> 0.37898048 | U9: =C9/(AD$4+H9+$T9) -> 0.00019283972 | V9: =D9/(AE$4+I9+$T9) -> 5.5615596e-05 | W9: =E9/(AF$4+J9+$T9) -> 0.00032555871 | X9: =F9/(AG$4+K9+$T9) -> 1.7436657e-05 | Y9: =G9/(AH$4+L9+$T9) -> 1.0815697e-05 | AA9: P3 | AB9: S3 | AC9: Creta | AD9: =SUMPRODUCT($B$3:$B$144,U$3:U$144,O$3:O$144) -> 7.0863181 | AE9: =SUMPRODUCT($B$3:$B$144,V$3:V$144,O$3:O$144) -> 2.0471772 | AF9: =SUMPRODUCT($B$3:$B$144,W$3:W$144,O$3:O$144) -> 11.826051 | AG9: =SUMPRODUCT($B$3:$B$144,X$3:X$144,O$3:O$144) -> 0.64294205 | AH9: =SUMPRODUCT($B$3:$B$144,Y$3:Y$144,O$3:O$144) -> 0.39887574 | AI9: =SUM(AD9:AH9) -> 22.001364 | AJ9: 19.9851 | AK9: 1 | AL9: =AI9-AJ9 -> 2.0162637
A10: Z8 | B10: =SUMIFS(Sectores!$C:$C,Sectores!$A:$A,$A10) -> 3739 | C10: =SUMIFS(Generacion!$C:$C,Generacion!$A:$A,$A10,Generacion!$B:$B,C$2) -> 0.043533877 | D10: =SUMIFS(Generacion!$C:$C,Generacion!$A:$A,$A10,Generacion!$B:$B,D$2) -> 0.037870933 | E10: =SUMIFS(Generacion!$C:$C,Generacion!$A:$A,$A10,Generacion!$B:$B,E$2) -> 0.01344949 | F10: =SUMIFS(Generacion!$C:$C,Generacion!$A:$A,$A10,Generacion!$B:$B,F$2) -> 0.0035393396 | G10: =SUMIFS(Generacion!$C:$C,Generacion!$A:$A,$A10,Generacion!$B:$B,G$2) -> 0.0024775377 | H10: =SUMPRODUCT((AtractivoAlternativas!$A$2:$A$931=$A10)*AtractivoAlternativas!$C$2:$C$931*COUNTIFS(Alternativas!$A$2:$A$51,AtractivoAlternativas!$B$2:$B$931,Alternativas!$B$2:$B$51,H$2)) -> 0 | I10: =SUMPRODUCT((AtractivoAlternativas!$A$2:$A$931=$A10)*AtractivoAlternativas!$C$2:$C$931*COUNTIFS(Alternativas!$A$2:$A$51,AtractivoAlternativas!$B$2:$B$931,Alternativas!$B$2:$B$51,I$2)) -> 0 | J10: =SUMPRODUCT((AtractivoAlternativas!$A$2:$A$931=$A10)*AtractivoAlternativas!$C$2:$C$931*COUNTIFS(Alternativas!$A$2:$A$51,AtractivoAlternativas!$B$2:$B$931,Alternativas!$B$2:$B$51,J$2)) -> 0 | K10: =SUMPRODUCT((AtractivoAlternativas!$A$2:$A$931=$A10)*AtractivoAlternativas!$C$2:$C$931*COUNTIFS(Alternativas!$A$2:$A$51,AtractivoAlternativas!$B$2:$B$931,Alternativas!$B$2:$B$51,K$2)) -> 0 | L10: =SUMPRODUCT((AtractivoAlternativas!$A$2:$A$931=$A10)*AtractivoAlternativas!$C$2:$C$931*COUNTIFS(Alternativas!$A$2:$A$51,AtractivoAlternativas!$B$2:$B$931,Alternativas!$B$2:$B$51,L$2)) -> 0 | M10: =SUMIFS(AtractivoSitios!$C:$C,AtractivoSitios!$A:$A,$A10,AtractivoSitios!$B:$B,M$2) -> 0 | N10: =SUMIFS(AtractivoSitios!$C:$C,AtractivoSitios!$A:$A,$A10,AtractivoSitios!$B:$B,N$2) -> 0.42147184 | O10: =SUMIFS(AtractivoSitios!$C:$C,AtractivoSitios!$A:$A,$A10,AtractivoSitios!$B:$B,O$2) -> 0 | P10: =SUMIFS(AtractivoSitios!$C:$C,AtractivoSitios!$A:$A,$A10,AtractivoSitios!$B:$B,P$2) -> 0 | Q10: =SUMIFS(AtractivoSitios!$C:$C,AtractivoSitios!$A:$A,$A10,AtractivoSitios!$B:$B,Q$2) -> 0 | R10: =SUMIFS(AtractivoSitios!$C:$C,AtractivoSitios!$A:$A,$A10,AtractivoSitios!$B:$B,R$2) -> 0 | S10: =SUMIFS(AtractivoSitios!$C:$C,AtractivoSitios!$A:$A,$A10,AtractivoSitios!$B:$B,S$2) -> 0 | T10: =SUM(M10:S10) -> 0.42147184 | U10: =C10/(AD$4+H10+$T10) -> 0.00019280343 | V10: =D10/(AE$4+I10+$T10) -> 5.5675089e-05 | W10: =E10/(AF$4+J10+$T10) -> 0.00032522421 | X10: =F10/(AG$4+K10+$T10) -> 1.7433008e-05 | Y10: =G10/(AH$4+L10+$T10) -> 1.0813691e-05 | AA10: P4 | AB10: S4 | AC10: Los Evangelistas | AD10: =SUMPRODUCT($B$3:$B$144,U$3:U$144,P$3:P$144) -> 8.4751015 | AE10: =SUMPRODUCT($B$3:$B$144,V$3:V$144,P$3:P$144) -> 2.4490003 | AF10: =SUMPRODUCT($B$3:$B$144,W$3:W$144,P$3:P$144) -> 14.084407 | AG10: =SUMPRODUCT($B$3:$B$144,X$3:X$144,P$3:P$144) -> 0.77038173 | AH10: =SUMPRODUCT($B$3:$B$144,Y$3:Y$144,P$3:P$144) -> 0.47797027 | AI10: =SUM(AD10:AH10) -> 26.256861 | AJ10: 13.3571 | AK10: 1 | AL10: =AI10-AJ10 -> 12.899761
A11: Z9 | B11: =SUMIFS(Sectores!$C:$C,Sectores!$A:$A,$A11) -> 1825 | C11: =SUMIFS(Generacion!$C:$C,Generacion!$A:$A,$A11,Generacion!$B:$B,C$2) -> 0.043533877 | D11: =SUMIFS(Generacion!$C:$C,Generacion!$A:$A,$A11,Generacion!$B:$B,D$2) -> 0.037870933 | E11: =SUMIFS(Generacion!$C:$C,Generacion!$A:$A,$A11,Generacion!$B:$B,E$2) -> 0.01344949 | F11: =SUMIFS(Generacion!$C:$C,Generacion!$A:$A,$A11,Generacion!$B:$B,F$2) -> 0.0035393396 | G11: =SUMIFS(Generacion!$C:$C,Generacion!$A:$A,$A11,Generacion!$B:$B,G$2) -> 0.0024775377 | H11: =SUMPRODUCT((AtractivoAlternativas!$A$2:$A$931=$A11)*AtractivoAlternativas!$C$2:$C$931*COUNTIFS(Alternativas!$A$2:$A$51,AtractivoAlternativas!$B$2:$B$931,Alternativas!$B$2:$B$51,H$2)) -> 0 | I11: =SUMPRODUCT((AtractivoAlternativas!$A$2:$A$931=$A11)*AtractivoAlternativas!$C$2:$C$931*COUNTIFS(Alternativas!$A$2:$A$51,AtractivoAlternativas!$B$2:$B$931,Alternativas!$B$2:$B$51,I$2)) -> 0.795907 | J11: =SUMPRODUCT((AtractivoAlternativas!$A$2:$A$931=$A11)*AtractivoAlternativas!$C$2:$C$931*COUNTIFS(Alternativas!$A$2:$A$51,AtractivoAlternativas!$B$2:$B$931,Alternativas!$B$2:$B$51,J$2)) -> 0 | K11: =SUMPRODUCT((AtractivoAlternativas!$A$2:$A$931=$A11)*AtractivoAlternativas!$C$2:$C$931*COUNTIFS(Alternativas!$A$2:$A$51,AtractivoAlternativas!$B$2:$B$931,Alternativas!$B$2:$B$51,K$2)) -> 0 | L11: =SUMPRODUCT((AtractivoAlternativas!$A$2:$A$931=$A11)*AtractivoAlternativas!$C$2:$C$931*COUNTIFS(Alternativas!$A$2:$A$51,AtractivoAlternativas!$B$2:$B$931,Alternativas!$B$2:$B$51,L$2)) -> 0 | M11: =SUMIFS(AtractivoSitios!$C:$C,AtractivoSitios!$A:$A,$A11,AtractivoSitios!$B:$B,M$2) -> 0 | N11: =SUMIFS(AtractivoSitios!$C:$C,AtractivoSitios!$A:$A,$A11,AtractivoSitios!$B:$B,N$2) -> 0.51012989 | O11: =SUMIFS(AtractivoSitios!$C:$C,AtractivoSitios!$A:$A,$A11,AtractivoSitios!$B:$B,O$2) -> 0 | P11: =SUMIFS(AtractivoSitios!$C:$C,AtractivoSitios!$A:$A,$A11,AtractivoSitios!$B:$B,P$2) -> 0 | Q11: =SUMIFS(AtractivoSitios!$C:$C,AtractivoSitios!$A:$A,$A11,AtractivoSitios!$B:$B,Q$2) -> 0.5520382 | R11: =SUMIFS(AtractivoSitios!$C:$C,AtractivoSitios!$A:$A,$A11,AtractivoSitios!$B:$B,R$2) -> 0 | S11: =SUMIFS(AtractivoSitios!$C:$C,AtractivoSitios!$A:$A,$A11,AtractivoSitios!$B:$B,S$2) -> 0 | T11: =SUM(M11:S11) -> 1.0621681 | U11: =C11/(AD$4+H11+$T11) -> 0.0001922579 | V11: =D11/(AE$4+I11+$T11) -> 5.5557751e-05 | W11: =E11/(AF$4+J11+$T11) -> 0.00032026245 | X11: =F11/(AG$4+K11+$T11) -> 1.7378167e-05 | Y11: =G11/(AH$4+L11+$T11) -> 1.0783535e-05 | AA11: P5 | AB11: S5 | AC11: Don Ramón | AD11: =SUMPRODUCT($B$3:$B$144,U$3:U$144,Q$3:Q$144) -> 13.712148 | AE11: =SUMPRODUCT($B$3:$B$144,V$3:V$144,Q$3:Q$144) -> 3.9619872 | AF11: =SUMPRODUCT($B$3:$B$144,W$3:W$144,Q$3:Q$144) -> 22.699642 | AG11: =SUMPRODUCT($B$3:$B$144,X$3:X$144,Q$3:Q$144) -> 1.2426533 | AH11: =SUMPRODUCT($B$3:$B$144,Y$3:Y$144,Q$3:Q$144) -> 0.77098108 | AI11: =SUM(AD11:AH11) -> 42.387411 | AJ11: 29.0401 | AK11: 1 | AL11: =AI11-AJ11 -> 13.347311
A12: Z10 | B12: =SUMIFS(Sectores!$C:$C,Sectores!$A:$A,$A12) -> 4171 | C12: =SUMIFS(Generacion!$C:$C,Generacion!$A:$A,$A12,Generacion!$B:$B,C$2) -> 0.043533877 | D12: =SUMIFS(Generacion!$C:$C,Generacion!$A:$A,$A12,Generacion!$B:$B,D$2) -> 0.037870933 | E12: =SUMIFS(Generacion!$C:$C,Generacion!$A:$A,$A12,Generacion!$B:$B,E$2) -> 0.01344949 | F12: =SUMIFS(Generacion!$C:$C,Generacion!$A:$A,$A12,Generacion!$B:$B,F$2) -> 0.0035393396 | G12: =SUMIFS(Generacion!$C:$C,Generacion!$A:$A,$A12,Generacion!$B:$B,G$2) -> 0.0024775377 | H12: =SUMPRODUCT((AtractivoAlternativas!$A$2:$A$931=$A12)*AtractivoAlternativas!$C$2:$C$931*COUNTIFS(Alternativas!$A$2:$A$51,AtractivoAlternativas!$B$2:$B$931,Alternativas!$B$2:$B$51,H$2)) -> 0 | I12: =SUMPRODUCT((AtractivoAlternativas!$A$2:$A$931=$A12)*AtractivoAlternativas!$C$2:$C$931*COUNTIFS(Alternativas!$A$2:$A$51,AtractivoAlternativas!$B$2:$B$931,Alternativas!$B$2:$B$51,I$2)) -> 0.6181238 | J12: =SUMPRODUCT((AtractivoAlternativas!$A$2:$A$931=$A12)*AtractivoAlternativas!$C$2:$C$931*COUNTIFS(Alternativas!$A$2:$A$51,AtractivoAlternativas!$B$2:$B$931,Alternativas!$B$2:$B$51,J$2)) -> 0 | K12: =SUMPRODUCT((AtractivoAlternativas!$A$2:$A$931=$A12)*AtractivoAlternativas!$C$2:$C$931*COUNTIFS(Alternativas!$A$2:$A$51,AtractivoAlternativas!$B$2:$B$931,Alternativas!$B$2:$B$51,K$2)) -> 0 | L12: =SUMPRODUCT((AtractivoAlternativas!$A$2:$A$931=$A12)*AtractivoAlternativas!$C$2:$C$931*COUNTIFS(Alternativas!$A$2:$A$51,AtractivoAlternativas!$B$2:$B$931,Alternativas!$B$2:$B$51,L$2)) -> 0 | M12: =SUMIFS(AtractivoSitios!$C:$C,AtractivoSitios!$A:$A,$A12,AtractivoSitios!$B:$B,M$2) -> 0 | N12: =SUMIFS(AtractivoSitios!$C:$C,AtractivoSitios!$A:$A,$A12,AtractivoSitios!$B:$B,N$2) -> 0.53102327 | O12: =SUMIFS(AtractivoSitios!$C:$C,AtractivoSitios!$A:$A,$A12,AtractivoSitios!$B:$B,O$2) -> 0 | P12: =SUMIFS(AtractivoSitios!$C:$C,AtractivoSitios!$A:$A,$A12,AtractivoSitios!$B:$B,P$2) -> 0 | Q12: =SUMIFS(AtractivoSitios!$C:$C,AtractivoSitios!$A:$A,$A12,AtractivoSitios!$B:$B,Q$2) -> 0 | R12: =SUMIFS(AtractivoSitios!$C:$C,AtractivoSitios!$A:$A,$A12,AtractivoSitios!$B:$B,R$2) -> 0 | S12: =SUMIFS(AtractivoSitios!$C:$C,AtractivoSitios!$A:$A,$A12,AtractivoSitios!$B:$B,S$2) -> 0 | T12: =SUM(M12:S12) -> 0.53102327 | U12: =C12/(AD$4+H12+$T12) -> 0.00019270993 | V12: =D12/(AE$4+I12+$T12) -> 5.5615592e-05 | W12: =E12/(AF$4+J12+$T12) -> 0.00032436494 | X12: =F12/(AG$4+K12+$T12) -> 1.7423606e-05 | Y12: =G12/(AH$4+L12+$T12) -> 1.0808523e-05 | AA12: P6 | AB12: S6 | AC12: Madre Tierra | AD12: =SUMPRODUCT($B$3:$B$144,U$3:U$144,R$3:R$144) -> 11.244909 | AE12: =SUMPRODUCT($B$3:$B$144,V$3:V$144,R$3:R$144) -> 3.2639023 | AF12: =SUMPRODUCT($B$3:$B$144,W$3:W$144,R$3:R$144) -> 18.383666 | AG12: =SUMPRODUCT($B$3:$B$144,X$3:X$144,R$3:R$144) -> 1.0236734 | AH12: =SUMPRODUCT($B$3:$B$144,Y$3:Y$144,R$3:R$144) -> 0.63531542 | AI12: =SUM(AD12:AH12) -> 34.551467 | AJ12: 30.7364 | AK12: 1 | AL12: =AI12-AJ12 -> 3.8150666
A13: Z11 | B13: =SUMIFS(Sectores!$C:$C,Sectores!$A:$A,$A13) -> 2572 | C13: =SUMIFS(Generacion!$C:$C,Generacion!$A:$A,$A13,Generacion!$B:$B,C$2) -> 0.043533877 | D13: =SUMIFS(Generacion!$C:$C,Generacion!$A:$A,$A13,Generacion!$B:$B,D$2) -> 0.037870933 | E13: =SUMIFS(Generacion!$C:$C,Generacion!$A:$A,$A13,Generacion!$B:$B,E$2) -> 0.01344949 | F13: =SUMIFS(Generacion!$C:$C,Generacion!$A:$A,$A13,Generacion!$B:$B,F$2) -> 0.0035393396 | G13: =SUMIFS(Generacion!$C:$C,Generacion!$A:$A,$A13,Generacion!$B:$B,G$2) -> 0.0024775377 | H13: =SUMPRODUCT((AtractivoAlternativas!$A$2:$A$931=$A13)*AtractivoAlternativas!$C$2:$C$931*COUNTIFS(Alternativas!$A$2:$A$51,AtractivoAlternativas!$B$2:$B$931,Alternativas!$B$2:$B$51,H$2)) -> 0 | I13: =SUMPRODUCT((AtractivoAlternativas!$A$2:$A$931=$A13)*AtractivoAlternativas!$C$2:$C$931*COUNTIFS(Alternativas!$A$2:$A$51,AtractivoAlternativas!$B$2:$B$931,Alternativas!$B$2:$B$51,I$2)) -> 0.88566906 | J13: =SUMPRODUCT((AtractivoAlternativas!$A$2:$A$931=$A13)*AtractivoAlternativas!$C$2:$C$931*COUNTIFS(Alternativas!$A$2:$A$51,AtractivoAlternativas!$B$2:$B$931,Alternativas!$B$2:$B$51,J$2)) -> 0 | K13: =SUMPRODUCT((AtractivoAlternativas!$A$2:$A$931=$A13)*AtractivoAlternativas!$C$2:$C$931*COUNTIFS(Alternativas!$A$2:$A$51,AtractivoAlternativas!$B$2:$B$931,Alternativas!$B$2:$B$51,K$2)) -> 0 | L13: =SUMPRODUCT((AtractivoAlternativas!$A$2:$A$931=$A13)*AtractivoAlternativas!$C$2:$C$931*COUNTIFS(Alternativas!$A$2:$A$51,AtractivoAlternativas!$B$2:$B$931,Alternativas!$B$2:$B$51,L$2)) -> 0 | M13: =SUMIFS(AtractivoSitios!$C:$C,AtractivoSitios!$A:$A,$A13,AtractivoSitios!$B:$B,M$2) -> 0 | N13: =SUMIFS(AtractivoSitios!$C:$C,AtractivoSitios!$A:$A,$A13,AtractivoSitios!$B:$B,N$2) -> 0.76924544 | O13: =SUMIFS(AtractivoSitios!$C:$C,AtractivoSitios!$A:$A,$A13,AtractivoSitios!$B:$B,O$2) -> 0 | P13: =SUMIFS(AtractivoSitios!$C:$C,AtractivoSitios!$A:$A,$A13,AtractivoSitios!$B:$B,P$2) -> 0 | Q13: =SUMIFS(AtractivoSitios!$C:$C,AtractivoSitios!$A:$A,$A13,AtractivoSitios!$B:$B,Q$2) -> 0 | R13: =SUMIFS(AtractivoSitios!$C:$C,AtractivoSitios!$A:$A,$A13,AtractivoSitios!$B:$B,R$2) -> 0 | S13: =SUMIFS(AtractivoSitios!$C:$C,AtractivoSitios!$A:$A,$A13,AtractivoSitios!$B:$B,S$2) -> 0 | T13: =SUM(M13:S13) -> 0.76924544 | U13: =C13/(AD$4+H13+$T13) -> 0.00019250693 | V13: =D13/(AE$4+I13+$T13) -> 5.5574315e-05 | W13: =E13/(AF$4+J13+$T13) -> 0.00032251202 | X13: =F13/(AG$4+K13+$T13) -> 1.7403197e-05 | Y13: =G13/(AH$4+L13+$T13) -> 1.0797301e-05 | AA13: P7 | AB13: S7 | AC13: Santa Faustina | AD13: =SUMPRODUCT($B$3:$B$144,U$3:U$144,S$3:S$144) -> 10.65232 | AE13: =SUMPRODUCT($B$3:$B$144,V$3:V$144,S$3:S$144) -> 3.0887284 | AF13: =SUMPRODUCT($B$3:$B$144,W$3:W$144,S$3:S$144) -> 17.366048 | AG13: =SUMPRODUCT($B$3:$B$144,X$3:X$144,S$3:S$144) -> 0.96977329 | AH13: =SUMPRODUCT($B$3:$B$144,Y$3:Y$144,S$3:S$144) -> 0.60180742 | AI13: =SUM(AD13:AH13) -> 32.678677 | AJ13: 5.1816 | AK13: 0 | AL13: =AI13-AJ13 -> 27.497077
